<class 'str'> <class 'str'>
0
<class 'str'> <class 'str'>
1
<class 'str'> <class 'str'>
2
<class 'str'> <class 'str'>
3
<class 'str'> <class 'str'>
Traceback (most recent call last):
  File "/Users/sudharsansundar/PycharmProjects/CS221_Milestone/venv/together_eval_script.py", line 149, in <module>
    main()
  File "/Users/sudharsansundar/PycharmProjects/CS221_Milestone/venv/together_eval_script.py", line 119, in main
    testresults1 = model_eval(eval_lev,
  File "/Users/sudharsansundar/PycharmProjects/CS221_Milestone/venv/together_eval_script.py", line 85, in model_eval
    pred = model_completion(prompt, model=model)
  File "/Users/sudharsansundar/PycharmProjects/CS221_Milestone/venv/together_eval_script.py", line 39, in model_completion
    response = together.Complete.create(prompt=prompt,
  File "/Users/sudharsansundar/PycharmProjects/CS221_Milestone/venv/lib/python3.8/site-packages/together/complete.py", line 44, in create
    response = create_post_request(
  File "/Users/sudharsansundar/PycharmProjects/CS221_Milestone/venv/lib/python3.8/site-packages/together/utils.py", line 110, in create_post_request
    response.raise_for_status()
  File "/Users/sudharsansundar/PycharmProjects/CS221_Milestone/venv/lib/python3.8/site-packages/requests/models.py", line 1021, in raise_for_status
    raise HTTPError(http_error_msg, response=self)
requests.exceptions.HTTPError: 400 Client Error: Bad Request for url: https://api.together.xyz/api/inference